<?xml version="1.0"?>
<robot xmlns:xacro="http://ros.org/wiki/xacro" name="mobile_robot">
  <xacro:include filename="$(find ur_description)/urdf/inc/ur5_macro.xacro"/>
  <link name="base_link">
    <visual>
      <geometry>
        <box size="0.8 0.8 0.1"/>
      </geometry>
      <material name="blue">
        <color rgba="0 0 1 1"/> </material>
    </visual>
    <collision>
      <geometry>
        <box size="0.8 0.8 0.1"/>
      </geometry>
    </collision>
    <inertial>
      <mass value="5"/> 
      <origin xyz="0 0 0" rpy="0 0 0"/> 
      <inertia ixx="0.708333" ixy="0.0" ixz="0.0" iyy="0.708333" iyz="0.0" izz="1.333333"/>    
     </inertial>
  </link>

    <link name="tru_giua">
        <visual>
            <geometry>
                <cylinder length="0.18" radius="0.03"/>
            </geometry>
            <material name ="tru">
                <color rgba="0.0 1.0 0.0 1.0"/>
            </material>
        </visual>
        <collision>
            <geometry>
                <cylinder length="0.18" radius="0.03"/>
            </geometry>
        </collision>
        <inertial>
            <mass value="0.1"/>          
            <inertia ixx="0.001" ixy="0.0" ixz="0.0"  iyy="0.001" iyz="0.0" izz="0.001" />     
         </inertial>
        <origin xyz="0 0 0"/>
  </link>

  <joint name="tru_giua_joint" type="fixed">
        <parent link="base_link"/>
        <child link="tru_giua"/>
        <origin xyz="0 0 0.14"/>
  </joint>

  <joint name="base_to_ur5_base" type="fixed">
    <parent link="base_link"/>
    <child link="ur5_base_link"/>  <!-- Sửa thành tên liên kết chính xác -->
    <origin xyz="0.02 0 0.05" rpy="0 0 0"/>
   </joint>
   <!-- Include UR5 -->
  <xacro:ur5_robot prefix="ur5_" /> 
  
  <link name="befor_left_wheel">
    <visual>
      <geometry>
        <cylinder length="0.05" radius="0.05"/> </geometry>
      <material name="red_material">
        <color rgba="1 1 0 1"/> </material>
    </visual>
    <collision>
      <geometry>
        <cylinder length="0.05" radius="0.05"/>
      </geometry>
   <surface>
      <friction>
        <ode>
          <mu>1.0</mu>
          <mu2>1.0</mu2>
        </ode>
      </friction>
    </surface>
    </collision>
    <inertial>
      <mass value="0.1"/>
      <origin xyz="0 0 0" rpy="0 0 0"/>
      <inertia ixx="0.002625" ixy="-0.00225" ixz="0.00075" iyy="0.00256583" iyz="0.00075" izz="0.00456583"/>     
    </inertial>
  </link>

  <joint name="joint_befor_left" type="continuous"> 
    <parent link="base_link"/>
    <child link="befor_left_wheel"/>
    <origin xyz="0.4 0.4 -0.05" rpy="0 1.570796 1.570796"/> <axis xyz="0 0 1"/> 
  </joint>

  <link name="befor_right_wheel">
    <visual>
      <geometry>
        <cylinder length="0.05" radius="0.05"/>
      </geometry>
      <material name="green_material">
        <color rgba="1 1 0 1"/> </material>
    </visual>
    <collision>
      <geometry>
        <cylinder length="0.05" radius="0.05"/>
      </geometry>
    <surface>
      <friction>
        <ode>
          <mu>1.0</mu>
          <mu2>1.0</mu2>
        </ode>
      </friction>
    </surface>
    </collision>
    <inertial>
      <mass value="0.1"/>
      <origin xyz="0 0 0" rpy="0 0 0"/>
      <inertia ixx="0.002625" ixy="-0.00225" ixz="0.00075" iyy="0.00256583" iyz="0.00075" izz="0.00456583"/>     
    </inertial>
  </link>

  <joint name="joint_befor_right" type="continuous">
    <parent link="base_link"/>
    <child link="befor_right_wheel"/>
    <origin xyz="0.4 -0.4 -0.05" rpy="0 1.570796 1.570796"/>
    <axis xyz="0 0 1"/>
  </joint>

  <link name="after_left_wheel">
    <visual>
      <geometry>
        <cylinder length="0.05" radius="0.05"/>
      </geometry>
      <material name="yellow_material">
        <color rgba="1 1 0 1"/> </material>
    </visual>
    <collision>
      <geometry>
        <cylinder length="0.05" radius="0.05"/>
      </geometry>
       <surface>
      <friction>
        <ode>
          <mu>1.0</mu>
          <mu2>1.0</mu2>
        </ode>
      </friction>
    </surface>
    </collision>
    <inertial>
      <mass value="0.1"/>
      <origin xyz="0 0 0" rpy="0 0 0"/>
      <inertia ixx="0.002625" ixy="-0.00225" ixz="0.00075" iyy="0.00256583" iyz="0.00075" izz="0.00456583"/>     
    </inertial>
  </link>

  <joint name="joint_after_left" type="continuous">
    <parent link="base_link"/>
    <child link="after_left_wheel"/>
    <origin xyz="-0.4 0.4 -0.05" rpy="0 1.570796 1.570796"/>
    <axis xyz="0 0 1"/>
  </joint>

  <link name="after_right_wheel">
    <visual>
      <geometry>
        <cylinder length="0.05" radius="0.05"/>
      </geometry>
      <material name="grey_material">
        <color rgba="0.5 0.5 0.5 1"/> </material>
    </visual>
    <collision>
      <geometry>
        <cylinder length="0.05" radius="0.05"/>
      </geometry>
     <surface>
      <friction>
        <ode>
          <mu>1.0</mu>
          <mu2>1.0</mu2>
        </ode>
      </friction>
    </surface>
    </collision>
    <inertial>
      <mass value="0.1"/>
      <origin xyz="0 0 0" rpy="0 0 0"/>
      <inertia ixx="0.002625" ixy="-0.00225" ixz="0.00075" iyy="0.00256583" iyz="0.00075" izz="0.00456583"/>     
    </inertial>
  </link>

  <joint name="joint_after_right" type="continuous">
    <parent link="base_link"/>
    <child link="after_right_wheel"/>
    <origin xyz="-0.4 -0.4 -0.05" rpy="0 1.570796 1.570796"/> <axis xyz="0 0 1"/>
  </joint>
 
  <link name="lidar_link">
        <visual>
            <geometry>
                <cylinder length="0.05" radius="0.055"/>
            </geometry>
            <material name ="lidar">
                <color rgba="0.0 1.0 0.0 1.0"/>
            </material>
        </visual>
        <collision>
            <geometry>
                <cylinder length="0.05" radius="0.055"/>
            </geometry>
        </collision>
        <inertial>
            <mass value="0.1"/>          
            <inertia ixx="0.001" ixy="0.0" ixz="0.0"  iyy="0.001" iyz="0.0" izz="0.001" />     
         </inertial>
        <origin xyz="0 0 0"/>
  </link>

  <joint name="lidar_joint" type="fixed">
        <parent link="base_link"/>
        <child link="lidar_link"/>
        <origin xyz="0 0 0.25"/>
  </joint>

   <!----> <gazebo reference="lidar_link">
        <sensor type="ray" name="lidar_sensor">
                  <pose>0 0 0 0 0 0</pose>
      <visualize>true</visualize>
      <update_rate>05</update_rate>
         <ray>
          <scan>
            <horizontal>
              <samples>360</samples>
              <resolution>1</resolution>
              <min_angle>0.0</min_angle>
              <max_angle>6.28319</max_angle>
          </horizontal>
        </scan>
        <range>
          <min>0.5</min>
          <max>10</max>
          <resolution>0.015</resolution>
        </range>
        <noise>
          <type>gaussian</type>
          <mean>0.0</mean>
          <stddev>0.01</stddev>
        </noise>
         </ray>
            <plugin name="gazebo_ros_laser" filename="libgazebo_ros_laser.so">
                <topicName>/scan</topicName>
                <frameName>lidar_link</frameName>
            </plugin>
        </sensor>
  </gazebo>
  
  <link name="camera_link">
        <visual>
            <geometry>
                <box size="0.1 0.1 0.05"/>
            </geometry>
            <material name ="camera">
                <color rgba="0.0 1.0 0.0 1.0"/>
            </material>
        </visual>
        <collision>
            <geometry>
                <box size="0.1 0.1 0.05"/>
            </geometry>
        </collision>
        <inertial>
            <mass value="0.1"/>          
            <inertia ixx="0.0001042" iyy="0.0001042" izz="0.0001667" ixy="0.0" ixz="0.0" iyz="0.0"/>
        </inertial>
        <origin xyz="0 0 0"/>
  </link>

  <joint name="camera_joint" type="fixed">
        <parent link="lidar_link"/>
        <child link="camera_link"/>
        <origin xyz="0.01 0 0.05"/>
  </joint>

 <gazebo reference="camera_link">
  <sensor type="camera" name="camera_sensor">
    <visualize>true</visualize>
    <pose> 0 0 0 0 0 0 </pose>
    <update_rate>10</update_rate>
    <camera>
      <horizontal_fov>1.3962634</horizontal_fov>
      <image>
        <width>640</width>
        <height>480</height>
        <format>R8G8B8</format>
      </image>
      <clip>
        <near>0.05</near>
        <far>100</far>
      </clip>
    </camera>
    <plugin name="gazebo_ros_camera" filename="libgazebo_ros_camera.so">
      <alwaysOn>true</alwaysOn>
      <updateRate>30</updateRate>
      <cameraName>camera</cameraName>
      <imageTopicName>image_raw</imageTopicName>
      <cameraInfoTopicName>camera_info</cameraInfoTopicName>
      <frameName>camera_link</frameName>
    </plugin>
  </sensor>
 </gazebo>


<!-- 
  <link name="court"> 
    <visual>
      <geometry>
        <box size="15 8 0.01"/> 
      </geometry>
      <material name="court_color">
       <color rgba="0.75 0.75 0.75 1"/>
      </material>
    </visual>
    <collision>
      <geometry>
        <box size="15 8 0.01"/>
      </geometry>
    </collision>
  </link>

  <link name="cot">
    <visual>
      <geometry>
        <cylinder length="2.43" radius="10.01"/>
      </geometry>
      <material name="court_color">
        <color rgba="0.75 0.75 0.75 1"/>
      </material>    
    </visual>
    <collision>
      <geometry>
        <cylinder length="2.43" radius="10.01"/>
      </geometry>
    </collision>
  </link> 

  
  <joint name="robot_to_court" type="fixed"> 
    <parent link="court"/>
    <child link="base_link"/>
    <origin xyz="-7.3 3.8 0.1" rpy="0 0 0"/>
  </joint>

   
  <joint name="cot_joint" type="fixed"> 
      <parent link="court"/>
      <child link="cot"/>
      <origin xyz="7.5 0 1.215" rpy="0 0 0"/>
  </joint> 
-->
<gazebo>
    <plugin name="diff_drive" filename="libgazebo_ros_diff_drive.so">
        <!-- Joint Names -->
        <leftJoint>joint_befor_left</leftJoint>
        <rightJoint>joint_befor_right</rightJoint>
       <!-- <leftJoint>joint_after_left</leftJoint>-->
        <!--<rightJoint>joint_after_right</rightJoint>-->

        <!-- Wheel Properties -->
        <wheelSeparation>0.25</wheelSeparation>
        <wheelDiameter>0.05</wheelDiameter>

        <!-- Control Topic -->

        <commandTopic>/cmd_vel</commandTopic>

        <!-- Odometry and Frames -->
        <odometryTopic>/odom</odometryTopic>
        <odometryFrame>odom</odometryFrame>
        <odometrySource>world</odometrySource>
        <robotBaseFrame>base_link</robotBaseFrame>

        <!-- Publish Options -->
        <publishOdomTF>true</publishOdomTF>
        <publishWheelTF>true</publishWheelTF>
        <publishTf>true</publishTf>
        <publishWheelJointState>true</publishWheelJointState>
        <!-- Wheel Dynamics -->
        <wheelAcceleration>100.0</wheelAcceleration>
        <wheelTorque>100.0</wheelTorque>
        <updateRate>100</updateRate>

        <rosDebugLevel>na</rosDebugLevel>
    </plugin>
</gazebo>

</robot>
