<?xml version="1.0"?>
<robot name="your_robot_name">

  <link name="base_link">
    <visual>
      <geometry>
         <mesh filename="package://baocao/src/meshes/base.stl" scale="0.001 0.001 0.001"/>
        </geometry>
      <material name="blue">
        <color rgba="0 0 1 1"/> </material>
    </visual>
    <collision>
      <geometry>
         <mesh filename="package://baocao/src/meshes/base.stl" scale="0.001 0.001 0.001"/>
      </geometry>
    </collision>
    <inertial>
      <mass value="5"/> 
      <origin xyz="0 0 0" rpy="0 0 0"/> 
      <inertia ixx="0.07083333" ixy="0.0" ixz="0.0" iyy="0.07083333" iyz="0.0" izz="0.13333333"/>     </inertial>
  </link>

  <link name="befor_left_wheel">
    <visual>
      <geometry>
        <cylinder length="0.05" radius="0.05"/> </geometry>
      <material name="red_material">
        <color rgba="1 1 0 1"/> </material>
    </visual>
    <collision>
      <geometry>
        <cylinder length="0.05" radius="0.05"/>
      </geometry>
   <surface>
      <friction>
        <ode>
          <mu>1.0</mu>
          <mu2>1.0</mu2>
        </ode>
      </friction>
    </surface>
    </collision>
    <inertial>
      <mass value="0.1"/>
      <origin xyz="0 0 0" rpy="0 0 0"/>
      <inertia ixx="0.002625" ixy="-0.00225" ixz="0.00075" iyy="0.00256583" iyz="0.00075" izz="0.00456583"/>     
    </inertial>
  </link>

  <joint name="joint_befor_left" type="continuous"> <parent link="base_link"/>
    <child link="befor_left_wheel"/>
    <origin xyz="0.14 0.125 -0.05" rpy="0 1.570796 1.570796"/> <axis xyz="0 0 1"/> 
  </joint>

  <link name="befor_right_wheel">
    <visual>
      <geometry>
        <cylinder length="0.05" radius="0.05"/>
      </geometry>
      <material name="green_material">
        <color rgba="1 1 0 1"/> </material>
    </visual>
    <collision>
      <geometry>
        <cylinder length="0.05" radius="0.05"/>
      </geometry>
    <surface>
      <friction>
        <ode>
          <mu>1.0</mu>
          <mu2>1.0</mu2>
        </ode>
      </friction>
    </surface>
    </collision>
    <inertial>
      <mass value="0.1"/>
      <origin xyz="0 0 0" rpy="0 0 0"/>
      <inertia ixx="0.002625" ixy="-0.00225" ixz="0.00075" iyy="0.00256583" iyz="0.00075" izz="0.00456583"/>     
    </inertial>
  </link>

  <joint name="joint_befor_right" type="continuous">
    <parent link="base_link"/>
    <child link="befor_right_wheel"/>
    <origin xyz="0.14 -0.125 -0.05" rpy="0 1.570796 1.570796"/>
    <axis xyz="0 0 1"/>
  </joint>

  <link name="after_left_wheel">
    <visual>
      <geometry>
        <cylinder length="0.05" radius="0.05"/>
      </geometry>
      <material name="yellow_material">
        <color rgba="1 1 0 1"/> </material>
    </visual>
    <collision>
      <geometry>
        <cylinder length="0.05" radius="0.05"/>
      </geometry>
       <surface>
      <friction>
        <ode>
          <mu>1.0</mu>
          <mu2>1.0</mu2>
        </ode>
      </friction>
    </surface>
    </collision>
    <inertial>
      <mass value="0.1"/>
      <origin xyz="0 0 0" rpy="0 0 0"/>
      <inertia ixx="0.002625" ixy="-0.00225" ixz="0.00075" iyy="0.00256583" iyz="0.00075" izz="0.00456583"/>     
    </inertial>
  </link>

  <joint name="joint_after_left" type="continuous">
    <parent link="base_link"/>
    <child link="after_left_wheel"/>
    <origin xyz="-0.14 0.125 -0.05" rpy="0 1.570796 1.570796"/>
    <axis xyz="0 0 1"/>
  </joint>

  <link name="after_right_wheel">
    <visual>
      <geometry>
        <cylinder length="0.05" radius="0.05"/>
      </geometry>
      <material name="grey_material">
        <color rgba="0.5 0.5 0.5 1"/> </material>
    </visual>
    <collision>
      <geometry>
        <cylinder length="0.05" radius="0.05"/>
      </geometry>
     <surface>
      <friction>
        <ode>
          <mu>1.0</mu>
          <mu2>1.0</mu2>
        </ode>
      </friction>
    </surface>
    </collision>
    <inertial>
      <mass value="0.1"/>
      <origin xyz="0 0 0" rpy="0 0 0"/>
      <inertia ixx="0.002625" ixy="-0.00225" ixz="0.00075" iyy="0.00256583" iyz="0.00075" izz="0.00456583"/>     
    </inertial>
  </link>

  <joint name="joint_after_right" type="continuous">
    <parent link="base_link"/>
    <child link="after_right_wheel"/>
    <origin xyz="-0.14 -0.125 -0.05" rpy="0 1.570796 1.570796"/> <axis xyz="0 0 1"/>
  </joint>

  <link name="lidar_link">
        <visual>
            <geometry>
                <box size="0.1 0.1 0.05"/>
            </geometry>
            <material name ="lidar">
                <color rgba="0.0 1.0 0.0 1.0"/>
            </material>
        </visual>
        <collision>
            <geometry>
                <box size="0.1 0.1 0.05"/>
            </geometry>
        </collision>
        <inertial>
            <mass value="0.1"/>          
            <inertia ixx="0.0001042" iyy="0.0001042" izz="0.0001667" ixy="0.0" ixz="0.0" iyz="0.0"/>
        </inertial>
        <origin xyz="0 0 0.15"/>
    </link>

    <joint name="lidar_joint" type="fixed">
        <parent link="base_link"/>
        <child link="lidar_link"/>
        <origin xyz="0 0 0.05"/>
    </joint>

    <gazebo reference="lidar_link">
        <sensor type="ray" name="lidar_sensor">
            <update_rate>10</update_rate>
            <ray>
                <scan>
                    <horizontal>
                        <samples>360</samples>
                        <resolution>1.0</resolution>
                        <min_angle>-1.57</min_angle>
                        <max_angle>1.57</max_angle>
                    </horizontal>
                </scan>
                <range>
                    <min>0.1</min>
                    <max>10.0</max>
                    <resolution>0.01</resolution>
                </range>
            </ray>
            <plugin name="gazebo_ros_laser" filename="libgazebo_ros_laser.so">
                <topicName>/scan</topicName>
                <frameName>lidar_link</frameName>
            </plugin>
        </sensor>
    </gazebo>
  

  <link name="camera_link">
        <visual>
            <geometry>
                <box size="0.1 0.1 0.05"/>
            </geometry>
            <material name ="camera">
                <color rgba="0.0 1.0 0.0 1.0"/>
            </material>
        </visual>
        <collision>
            <geometry>
                <box size="0.1 0.1 0.05"/>
            </geometry>
        </collision>
        <inertial>
            <mass value="0.1"/>          
            <inertia ixx="0.0001042" iyy="0.0001042" izz="0.0001667" ixy="0.0" ixz="0.0" iyz="0.0"/>
        </inertial>
        <origin xyz="0 0 0.15"/>
  </link>

  <joint name="camera_joint" type="fixed">
        <parent link="lidar_link"/>
        <child link="camera_link"/>
        <origin xyz="0 0 0.05"/>
  </joint>

 <gazebo reference="camera_link">
  <sensor type="camera" name="camera_sensor">
    <update_rate>30</update_rate>
    <camera>
      <horizontal_fov>1.3962634</horizontal_fov>
      <image>
        <width>640</width>
        <height>480</height>
        <format>R8G8B8</format>
      </image>
      <clip>
        <near>0.1</near>
        <far>100</far>
      </clip>
    </camera>
    <plugin name="gazebo_ros_camera" filename="libgazebo_ros_camera.so">
      <alwaysOn>true</alwaysOn>
      <updateRate>30</updateRate>
      <cameraName>camera</cameraName>
      <imageTopicName>image_raw</imageTopicName>
      <cameraInfoTopicName>camera_info</cameraInfoTopicName>
      <frameName>camera_link</frameName>
    </plugin>
  </sensor>
 </gazebo>



 <!-- <link name="court"> 
    <visual>
      <geometry>
        <box size="15 8 0.01"/> 
      </geometry>
      <material name="court_color">
       <color rgba="0.75 0.75 0.75 1"/>
      </material>
    </visual>
    <collision>
      <geometry>
        <box size="15 8 0.01"/>
      </geometry>
    </collision>
  </link>

  <link name="cot">
    <visual>
      <geometry>
        <cylinder length="2.43" radius="0.01"/>
      </geometry>
      <material name="court_color">
        <color rgba="0.75 0.75 0.75 1"/>
      </material>    
    </visual>
    <collision>
      <geometry>
        <cylinder length="2.43" radius="0.01"/>
      </geometry>
    </collision>
  </link> 

  
  <joint name="robot_to_court" type="fixed"> 
    <parent link="court"/>
    <child link="base_link"/>
    <origin xyz="-7.3 3.8 0.1" rpy="0 0 0"/>
  </joint>

   
  <joint name="cot_joint" type="fixed"> 
      <parent link="court"/>
      <child link="cot"/>
      <origin xyz="7.5 0 1.215" rpy="0 0 0"/>
  </joint> -->

<gazebo>
    <plugin name="diff_drive" filename="libgazebo_ros_diff_drive.so">
        <!-- Joint Names -->
        <leftJoint>base_to_wheel_front_left</leftJoint>
        <rightJoint>base_to_wheel_front_right</rightJoint>
        <leftJoint>base_to_wheel_rear_left</leftJoint>
        <rightJoint>base_to_wheel_rear_right</rightJoint>

        <!-- Wheel Properties -->
        <wheelSeparation>0.25</wheelSeparation>
        <wheelDiameter>0.05</wheelDiameter>

        <!-- Control Topic -->

        <commandTopic>/cmd_vel</commandTopic>

        <!-- Odometry and Frames -->
        <odometryTopic>/odom</odometryTopic>
        <odometryFrame>odom</odometryFrame>
        <odometrySource>world</odometrySource>
        <robotBaseFrame>base_link</robotBaseFrame>

        <!-- Publish Options -->
        <publishOdomTF>true</publishOdomTF>
        <publishWheelTF>true</publishWheelTF>
        <publishTf>true</publishTf>
        <publishWheelJointState>true</publishWheelJointState>
        <!-- Wheel Dynamics -->
        <wheelAcceleration>10.0</wheelAcceleration>
        <wheelTorque>10.0</wheelTorque>
        <updateRate>100</updateRate>

        <rosDebugLevel>na</rosDebugLevel>
    </plugin>
</gazebo>

</robot>
